[2024-07-04T05:58:34.515+0000] {local_task_job_runner.py:120} INFO - ::group::Pre task execution logs
[2024-07-04T05:58:34.526+0000] {taskinstance.py:2076} INFO - Dependencies all met for dep_context=non-requeueable deps ti=<TaskInstance: prod_dag.run_scraping_docker scheduled__2024-07-02T00:00:00+00:00 [queued]>
[2024-07-04T05:58:34.529+0000] {taskinstance.py:2076} INFO - Dependencies all met for dep_context=requeueable deps ti=<TaskInstance: prod_dag.run_scraping_docker scheduled__2024-07-02T00:00:00+00:00 [queued]>
[2024-07-04T05:58:34.530+0000] {taskinstance.py:2306} INFO - Starting attempt 2 of 2
[2024-07-04T05:58:34.537+0000] {taskinstance.py:2330} INFO - Executing <Task(DockerOperator): run_scraping_docker> on 2024-07-02 00:00:00+00:00
[2024-07-04T05:58:34.540+0000] {warnings.py:112} WARNING - /home/***/.local/lib/python3.12/site-packages/***/task/task_runner/standard_task_runner.py:61: DeprecationWarning: This process (pid=130) is multi-threaded, use of fork() may lead to deadlocks in the child.
  pid = os.fork()

[2024-07-04T05:58:34.541+0000] {standard_task_runner.py:63} INFO - Started process 131 to run task
[2024-07-04T05:58:34.541+0000] {standard_task_runner.py:90} INFO - Running: ['***', 'tasks', 'run', 'prod_dag', 'run_scraping_docker', 'scheduled__2024-07-02T00:00:00+00:00', '--job-id', '281', '--raw', '--subdir', 'DAGS_FOLDER/DAG_prod.py', '--cfg-path', '/tmp/tmphaubuua2']
[2024-07-04T05:58:34.541+0000] {standard_task_runner.py:91} INFO - Job 281: Subtask run_scraping_docker
[2024-07-04T05:58:34.560+0000] {task_command.py:426} INFO - Running <TaskInstance: prod_dag.run_scraping_docker scheduled__2024-07-02T00:00:00+00:00 [running]> on host 223d981c4fb5
[2024-07-04T05:58:34.603+0000] {taskinstance.py:2648} INFO - Exporting env vars: AIRFLOW_CTX_DAG_OWNER='***' AIRFLOW_CTX_DAG_ID='prod_dag' AIRFLOW_CTX_TASK_ID='run_scraping_docker' AIRFLOW_CTX_EXECUTION_DATE='2024-07-02T00:00:00+00:00' AIRFLOW_CTX_TRY_NUMBER='2' AIRFLOW_CTX_DAG_RUN_ID='scheduled__2024-07-02T00:00:00+00:00'
[2024-07-04T05:58:34.603+0000] {taskinstance.py:430} INFO - ::endgroup::
[2024-07-04T05:58:34.611+0000] {docker.py:157} ERROR - Failed to establish connection to Docker host unix://var/run/docker.sock: Error while fetching server API version: ('Connection aborted.', PermissionError(13, 'Permission denied'))
[2024-07-04T05:58:34.611+0000] {taskinstance.py:441} INFO - ::group::Post task execution logs
[2024-07-04T05:58:34.615+0000] {taskinstance.py:2905} ERROR - Task failed with exception
Traceback (most recent call last):
  File "/home/airflow/.local/lib/python3.12/site-packages/airflow/models/taskinstance.py", line 465, in _execute_task
    result = _execute_callable(context=context, **execute_callable_kwargs)
             ^^^^^^^^^^^^^^^^^^^^^^^^^^^^^^^^^^^^^^^^^^^^^^^^^^^^^^^^^^^^^
  File "/home/airflow/.local/lib/python3.12/site-packages/airflow/models/taskinstance.py", line 432, in _execute_callable
    return execute_callable(context=context, **execute_callable_kwargs)
           ^^^^^^^^^^^^^^^^^^^^^^^^^^^^^^^^^^^^^^^^^^^^^^^^^^^^^^^^^^^^
  File "/home/airflow/.local/lib/python3.12/site-packages/airflow/models/baseoperator.py", line 401, in wrapper
    return func(self, *args, **kwargs)
           ^^^^^^^^^^^^^^^^^^^^^^^^^^^
  File "/home/airflow/.local/lib/python3.12/site-packages/airflow/providers/docker/operators/docker.py", line 492, in execute
    if self.force_pull or not self.cli.images(name=self.image):
                              ^^^^^^^^
  File "/home/airflow/.local/lib/python3.12/site-packages/airflow/providers/docker/operators/docker.py", line 362, in cli
    return self.hook.api_client
           ^^^^^^^^^^^^^^^^^^^^
  File "/usr/local/lib/python3.12/functools.py", line 995, in __get__
    val = self.func(instance)
          ^^^^^^^^^^^^^^^^^^^
  File "/home/airflow/.local/lib/python3.12/site-packages/airflow/providers/docker/hooks/docker.py", line 161, in api_client
    raise AirflowException("Failed to establish connection to any given Docker hosts.")
airflow.exceptions.AirflowException: Failed to establish connection to any given Docker hosts.
[2024-07-04T05:58:34.616+0000] {taskinstance.py:1206} INFO - Marking task as FAILED. dag_id=prod_dag, task_id=run_scraping_docker, run_id=scheduled__2024-07-02T00:00:00+00:00, execution_date=20240702T000000, start_date=20240704T055834, end_date=20240704T055834
[2024-07-04T05:58:34.622+0000] {standard_task_runner.py:110} ERROR - Failed to execute job 281 for task run_scraping_docker (Failed to establish connection to any given Docker hosts.; 131)
[2024-07-04T05:58:34.633+0000] {local_task_job_runner.py:240} INFO - Task exited with return code 1
[2024-07-04T05:58:34.644+0000] {taskinstance.py:3503} INFO - 0 downstream tasks scheduled from follow-on schedule check
[2024-07-04T05:58:34.648+0000] {local_task_job_runner.py:222} INFO - ::endgroup::
