[2024-07-05T10:36:17.547+0000] {local_task_job_runner.py:120} INFO - ::group::Pre task execution logs
[2024-07-05T10:36:17.564+0000] {taskinstance.py:2076} INFO - Dependencies all met for dep_context=non-requeueable deps ti=<TaskInstance: prod_dag.run_postgre_docker manual__2024-07-05T10:35:59.672821+00:00 [queued]>
[2024-07-05T10:36:17.567+0000] {taskinstance.py:2076} INFO - Dependencies all met for dep_context=requeueable deps ti=<TaskInstance: prod_dag.run_postgre_docker manual__2024-07-05T10:35:59.672821+00:00 [queued]>
[2024-07-05T10:36:17.568+0000] {taskinstance.py:2306} INFO - Starting attempt 1 of 2
[2024-07-05T10:36:17.576+0000] {taskinstance.py:2330} INFO - Executing <Task(DockerOperator): run_postgre_docker> on 2024-07-05 10:35:59.672821+00:00
[2024-07-05T10:36:17.586+0000] {warnings.py:112} WARNING - /home/***/.local/lib/python3.12/site-packages/***/task/task_runner/standard_task_runner.py:61: DeprecationWarning: This process (pid=149) is multi-threaded, use of fork() may lead to deadlocks in the child.
  pid = os.fork()

[2024-07-05T10:36:17.587+0000] {standard_task_runner.py:63} INFO - Started process 152 to run task
[2024-07-05T10:36:17.588+0000] {standard_task_runner.py:90} INFO - Running: ['***', 'tasks', 'run', 'prod_dag', 'run_postgre_docker', 'manual__2024-07-05T10:35:59.672821+00:00', '--job-id', '12', '--raw', '--subdir', 'DAGS_FOLDER/DAG_prod.py', '--cfg-path', '/tmp/tmpvvvzj2vg']
[2024-07-05T10:36:17.589+0000] {standard_task_runner.py:91} INFO - Job 12: Subtask run_postgre_docker
[2024-07-05T10:36:17.618+0000] {task_command.py:426} INFO - Running <TaskInstance: prod_dag.run_postgre_docker manual__2024-07-05T10:35:59.672821+00:00 [running]> on host 39db74c4aadf
[2024-07-05T10:36:17.713+0000] {taskinstance.py:2648} INFO - Exporting env vars: AIRFLOW_CTX_DAG_OWNER='***' AIRFLOW_CTX_DAG_ID='prod_dag' AIRFLOW_CTX_TASK_ID='run_postgre_docker' AIRFLOW_CTX_EXECUTION_DATE='2024-07-05T10:35:59.672821+00:00' AIRFLOW_CTX_TRY_NUMBER='1' AIRFLOW_CTX_DAG_RUN_ID='manual__2024-07-05T10:35:59.672821+00:00'
[2024-07-05T10:36:17.714+0000] {taskinstance.py:430} INFO - ::endgroup::
[2024-07-05T10:36:17.739+0000] {docker.py:366} INFO - Starting docker container from image bost67dst/postgre_loading
[2024-07-05T10:36:18.231+0000] {docker.py:436} INFO - python: can't open file '/app/src/postgre/CreatePostgre.py': [Errno 2] No such file or directory
[2024-07-05T10:36:18.401+0000] {taskinstance.py:441} INFO - ::group::Post task execution logs
[2024-07-05T10:36:18.408+0000] {taskinstance.py:2905} ERROR - Task failed with exception
Traceback (most recent call last):
  File "/home/airflow/.local/lib/python3.12/site-packages/airflow/models/taskinstance.py", line 465, in _execute_task
    result = _execute_callable(context=context, **execute_callable_kwargs)
             ^^^^^^^^^^^^^^^^^^^^^^^^^^^^^^^^^^^^^^^^^^^^^^^^^^^^^^^^^^^^^
  File "/home/airflow/.local/lib/python3.12/site-packages/airflow/models/taskinstance.py", line 432, in _execute_callable
    return execute_callable(context=context, **execute_callable_kwargs)
           ^^^^^^^^^^^^^^^^^^^^^^^^^^^^^^^^^^^^^^^^^^^^^^^^^^^^^^^^^^^^
  File "/home/airflow/.local/lib/python3.12/site-packages/airflow/models/baseoperator.py", line 401, in wrapper
    return func(self, *args, **kwargs)
           ^^^^^^^^^^^^^^^^^^^^^^^^^^^
  File "/home/airflow/.local/lib/python3.12/site-packages/airflow/providers/docker/operators/docker.py", line 509, in execute
    return self._run_image()
           ^^^^^^^^^^^^^^^^^
  File "/home/airflow/.local/lib/python3.12/site-packages/airflow/providers/docker/operators/docker.py", line 383, in _run_image
    return self._run_image_with_mounts(self.mounts, add_tmp_variable=False)
           ^^^^^^^^^^^^^^^^^^^^^^^^^^^^^^^^^^^^^^^^^^^^^^^^^^^^^^^^^^^^^^^^
  File "/home/airflow/.local/lib/python3.12/site-packages/airflow/providers/docker/operators/docker.py", line 444, in _run_image_with_mounts
    raise DockerContainerFailedException(f"Docker container failed: {result!r}", logs=log_lines)
airflow.providers.docker.exceptions.DockerContainerFailedException: Docker container failed: {'StatusCode': 2}
[2024-07-05T10:36:18.411+0000] {taskinstance.py:1206} INFO - Marking task as UP_FOR_RETRY. dag_id=prod_dag, task_id=run_postgre_docker, run_id=manual__2024-07-05T10:35:59.672821+00:00, execution_date=20240705T103559, start_date=20240705T103617, end_date=20240705T103618
[2024-07-05T10:36:18.423+0000] {standard_task_runner.py:110} ERROR - Failed to execute job 12 for task run_postgre_docker (Docker container failed: {'StatusCode': 2}; 152)
[2024-07-05T10:36:18.443+0000] {local_task_job_runner.py:240} INFO - Task exited with return code 1
[2024-07-05T10:36:18.460+0000] {taskinstance.py:3503} INFO - 0 downstream tasks scheduled from follow-on schedule check
[2024-07-05T10:36:18.465+0000] {local_task_job_runner.py:222} INFO - ::endgroup::
